<?xml version="1.0" ?>
<!-- =================================================================================== -->
<!-- |    This document was autogenerated by xacro from ./snake_robot_cit_description/urdf/snake_robot_cit.xacro | -->
<!-- |    EDITING THIS FILE BY HAND IS NOT RECOMMENDED                                 | -->
<!-- =================================================================================== -->
<robot name="snake_robot_cit">
  <material name="silver_default">
    <color rgba="0.700 0.700 0.700 1.000"/>
  </material>
  <material name="default">
    <color rgba="0.3137254901960784 0.3137254901960784 0.3137254901960784 1.0"/>
  </material>
  <transmission name="revjoint1_tran">
    <type>transmission_interface/SimpleTransmission</type>
    <joint name="revjoint1">
      <hardwareInterface>hardware_interface/EffortJointInterface</hardwareInterface>
    </joint>
    <actuator name="revjoint1_actr">
      <hardwareInterface>hardware_interface/EffortJointInterface</hardwareInterface>
      <mechanicalReduction>1</mechanicalReduction>
    </actuator>
  </transmission>
  <transmission name="revjoint2_tran">
    <type>transmission_interface/SimpleTransmission</type>
    <joint name="revjoint2">
      <hardwareInterface>hardware_interface/EffortJointInterface</hardwareInterface>
    </joint>
    <actuator name="revjoint2_actr">
      <hardwareInterface>hardware_interface/EffortJointInterface</hardwareInterface>
      <mechanicalReduction>1</mechanicalReduction>
    </actuator>
  </transmission>
  <transmission name="revjoint3_tran">
    <type>transmission_interface/SimpleTransmission</type>
    <joint name="revjoint3">
      <hardwareInterface>hardware_interface/EffortJointInterface</hardwareInterface>
    </joint>
    <actuator name="revjoint3_actr">
      <hardwareInterface>hardware_interface/EffortJointInterface</hardwareInterface>
      <mechanicalReduction>1</mechanicalReduction>
    </actuator>
  </transmission>
  <transmission name="revjoint4_tran">
    <type>transmission_interface/SimpleTransmission</type>
    <joint name="revjoint4">
      <hardwareInterface>hardware_interface/EffortJointInterface</hardwareInterface>
    </joint>
    <actuator name="revjoint4_actr">
      <hardwareInterface>hardware_interface/EffortJointInterface</hardwareInterface>
      <mechanicalReduction>1</mechanicalReduction>
    </actuator>
  </transmission>
  <transmission name="revjoint5_tran">
    <type>transmission_interface/SimpleTransmission</type>
    <joint name="revjoint5">
      <hardwareInterface>hardware_interface/EffortJointInterface</hardwareInterface>
    </joint>
    <actuator name="revjoint5_actr">
      <hardwareInterface>hardware_interface/EffortJointInterface</hardwareInterface>
      <mechanicalReduction>1</mechanicalReduction>
    </actuator>
  </transmission>
  <transmission name="revjoint6_tran">
    <type>transmission_interface/SimpleTransmission</type>
    <joint name="revjoint6">
      <hardwareInterface>hardware_interface/EffortJointInterface</hardwareInterface>
    </joint>
    <actuator name="revjoint6_actr">
      <hardwareInterface>hardware_interface/EffortJointInterface</hardwareInterface>
      <mechanicalReduction>1</mechanicalReduction>
    </actuator>
  </transmission>
  <transmission name="revjoint7_tran">
    <type>transmission_interface/SimpleTransmission</type>
    <joint name="revjoint7">
      <hardwareInterface>hardware_interface/EffortJointInterface</hardwareInterface>
    </joint>
    <actuator name="revjoint7_actr">
      <hardwareInterface>hardware_interface/EffortJointInterface</hardwareInterface>
      <mechanicalReduction>1</mechanicalReduction>
    </actuator>
  </transmission>
  <transmission name="revjoint8_tran">
    <type>transmission_interface/SimpleTransmission</type>
    <joint name="revjoint8">
      <hardwareInterface>hardware_interface/EffortJointInterface</hardwareInterface>
    </joint>
    <actuator name="revjoint8_actr">
      <hardwareInterface>hardware_interface/EffortJointInterface</hardwareInterface>
      <mechanicalReduction>1</mechanicalReduction>
    </actuator>
  </transmission>
  <transmission name="revjoint9_tran">
    <type>transmission_interface/SimpleTransmission</type>
    <joint name="revjoint9">
      <hardwareInterface>hardware_interface/EffortJointInterface</hardwareInterface>
    </joint>
    <actuator name="revjoint9_actr">
      <hardwareInterface>hardware_interface/EffortJointInterface</hardwareInterface>
      <mechanicalReduction>1</mechanicalReduction>
    </actuator>
  </transmission>
  <transmission name="revjoint10_tran">
    <type>transmission_interface/SimpleTransmission</type>
    <joint name="revjoint10">
      <hardwareInterface>hardware_interface/EffortJointInterface</hardwareInterface>
    </joint>
    <actuator name="revjoint10_actr">
      <hardwareInterface>hardware_interface/EffortJointInterface</hardwareInterface>
      <mechanicalReduction>1</mechanicalReduction>
    </actuator>
  </transmission>
  <link name="base_link">
    <inertial>
      <origin rpy="0 0 0" xyz="0.49333731311283335 1.158454640943659 0.019785748921786316"/>
      <mass value="2.4672394368378052"/>
      <inertia ixx="0.013192" ixy="7e-06" ixz="-0.0" iyy="0.00469" iyz="0.000587" izz="0.013535"/>
    </inertial>
    <visual>
      <origin rpy="0 0 0" xyz="0 0 0"/>
      <geometry>
        <mesh filename="package://snake_robot_cit_description/meshes/base_link.stl" scale="0.001 0.001 0.001"/>
      </geometry>
      <material name="default"/>
    </visual>
    <collision>
      <origin rpy="0 0 0" xyz="0 0 0"/>
      <geometry>
        <mesh filename="package://snake_robot_cit_description/meshes/base_link.stl" scale="0.001 0.001 0.001"/>
      </geometry>
    </collision>
  </link>
  <link name="onemodule1_1">
    <inertial>
      <origin rpy="0 0 0" xyz="-6.43198592636951e-06 -0.06684395997270809 0.045082314708387916"/>
      <mass value="0.718982525570161"/>
      <inertia ixx="0.001158" ixy="3e-06" ixz="0.0" iyy="0.001136" iyz="2.8e-05" izz="0.001592"/>
    </inertial>
    <visual>
      <origin rpy="0 0 0" xyz="-0.493459 -1.011872 0.043511"/>
      <geometry>
        <mesh filename="package://snake_robot_cit_description/meshes/onemodule1_1.stl" scale="0.001 0.001 0.001"/>
      </geometry>
      <material name="default"/>
    </visual>
    <collision>
      <origin rpy="0 0 0" xyz="-0.493459 -1.011872 0.043511"/>
      <geometry>
        <mesh filename="package://snake_robot_cit_description/meshes/onemodule1_1.stl" scale="0.001 0.001 0.001"/>
      </geometry>
    </collision>
  </link>
  <link name="onemodule2_1">
    <inertial>
      <origin rpy="0 0 0" xyz="-6.4703775745633685e-06 -0.06684388681472053 0.04508231470838813"/>
      <mass value="0.718982525570161"/>
      <inertia ixx="0.001158" ixy="3e-06" ixz="0.0" iyy="0.001136" iyz="2.8e-05" izz="0.001592"/>
    </inertial>
    <visual>
      <origin rpy="0 0 0" xyz="-0.493578 -0.869872 0.043511"/>
      <geometry>
        <mesh filename="package://snake_robot_cit_description/meshes/onemodule2_1.stl" scale="0.001 0.001 0.001"/>
      </geometry>
      <material name="default"/>
    </visual>
    <collision>
      <origin rpy="0 0 0" xyz="-0.493578 -0.869872 0.043511"/>
      <geometry>
        <mesh filename="package://snake_robot_cit_description/meshes/onemodule2_1.stl" scale="0.001 0.001 0.001"/>
      </geometry>
    </collision>
  </link>
  <link name="onemodule3_1">
    <inertial>
      <origin rpy="0 0 0" xyz="-6.5087692222576266e-06 -0.06684381365673298 0.045082314708388346"/>
      <mass value="0.718982525570161"/>
      <inertia ixx="0.001158" ixy="3e-06" ixz="0.0" iyy="0.001136" iyz="2.8e-05" izz="0.001592"/>
    </inertial>
    <visual>
      <origin rpy="0 0 0" xyz="-0.493697 -0.727872 0.043511"/>
      <geometry>
        <mesh filename="package://snake_robot_cit_description/meshes/onemodule3_1.stl" scale="0.001 0.001 0.001"/>
      </geometry>
      <material name="default"/>
    </visual>
    <collision>
      <origin rpy="0 0 0" xyz="-0.493697 -0.727872 0.043511"/>
      <geometry>
        <mesh filename="package://snake_robot_cit_description/meshes/onemodule3_1.stl" scale="0.001 0.001 0.001"/>
      </geometry>
    </collision>
  </link>
  <link name="onemodule4_1">
    <inertial>
      <origin rpy="0 0 0" xyz="-6.54716087067353e-06 -0.06684374049874575 0.04508231470838863"/>
      <mass value="0.718982525570161"/>
      <inertia ixx="0.001158" ixy="3e-06" ixz="0.0" iyy="0.001136" iyz="2.8e-05" izz="0.001592"/>
    </inertial>
    <visual>
      <origin rpy="0 0 0" xyz="-0.493816 -0.585872 0.043511"/>
      <geometry>
        <mesh filename="package://snake_robot_cit_description/meshes/onemodule4_1.stl" scale="0.001 0.001 0.001"/>
      </geometry>
      <material name="default"/>
    </visual>
    <collision>
      <origin rpy="0 0 0" xyz="-0.493816 -0.585872 0.043511"/>
      <geometry>
        <mesh filename="package://snake_robot_cit_description/meshes/onemodule4_1.stl" scale="0.001 0.001 0.001"/>
      </geometry>
    </collision>
  </link>
  <link name="onemodule5_1">
    <inertial>
      <origin rpy="0 0 0" xyz="-6.585552518811877e-06 -0.0668436673407582 0.045082314708388915"/>
      <mass value="0.718982525570161"/>
      <inertia ixx="0.001158" ixy="3e-06" ixz="0.0" iyy="0.001136" iyz="2.8e-05" izz="0.001592"/>
    </inertial>
    <visual>
      <origin rpy="0 0 0" xyz="-0.493935 -0.443872 0.043511"/>
      <geometry>
        <mesh filename="package://snake_robot_cit_description/meshes/onemodule5_1.stl" scale="0.001 0.001 0.001"/>
      </geometry>
      <material name="default"/>
    </visual>
    <collision>
      <origin rpy="0 0 0" xyz="-0.493935 -0.443872 0.043511"/>
      <geometry>
        <mesh filename="package://snake_robot_cit_description/meshes/onemodule5_1.stl" scale="0.001 0.001 0.001"/>
      </geometry>
    </collision>
  </link>
  <link name="onemodule6_1">
    <inertial>
      <origin rpy="0 0 0" xyz="-6.62394416722778e-06 -0.06684359418277025 0.04508231470838916"/>
      <mass value="0.718982525570161"/>
      <inertia ixx="0.001158" ixy="3e-06" ixz="0.0" iyy="0.001136" iyz="2.8e-05" izz="0.001592"/>
    </inertial>
    <visual>
      <origin rpy="0 0 0" xyz="-0.494054 -0.301872 0.043511"/>
      <geometry>
        <mesh filename="package://snake_robot_cit_description/meshes/onemodule6_1.stl" scale="0.001 0.001 0.001"/>
      </geometry>
      <material name="default"/>
    </visual>
    <collision>
      <origin rpy="0 0 0" xyz="-0.494054 -0.301872 0.043511"/>
      <geometry>
        <mesh filename="package://snake_robot_cit_description/meshes/onemodule6_1.stl" scale="0.001 0.001 0.001"/>
      </geometry>
    </collision>
  </link>
  <link name="onemodule7_1">
    <inertial>
      <origin rpy="0 0 0" xyz="-6.662335815199594e-06 -0.06684352102478269 0.04508231470838948"/>
      <mass value="0.718982525570161"/>
      <inertia ixx="0.001158" ixy="3e-06" ixz="0.0" iyy="0.001136" iyz="2.8e-05" izz="0.001592"/>
    </inertial>
    <visual>
      <origin rpy="0 0 0" xyz="-0.494173 -0.159872 0.043511"/>
      <geometry>
        <mesh filename="package://snake_robot_cit_description/meshes/onemodule7_1.stl" scale="0.001 0.001 0.001"/>
      </geometry>
      <material name="default"/>
    </visual>
    <collision>
      <origin rpy="0 0 0" xyz="-0.494173 -0.159872 0.043511"/>
      <geometry>
        <mesh filename="package://snake_robot_cit_description/meshes/onemodule7_1.stl" scale="0.001 0.001 0.001"/>
      </geometry>
    </collision>
  </link>
  <link name="onemodule8_1">
    <inertial>
      <origin rpy="0 0 0" xyz="-6.7007274635044745e-06 -0.06684344786679515 0.04508231470838973"/>
      <mass value="0.718982525570161"/>
      <inertia ixx="0.001158" ixy="3e-06" ixz="0.0" iyy="0.001136" iyz="2.8e-05" izz="0.001592"/>
    </inertial>
    <visual>
      <origin rpy="0 0 0" xyz="-0.494292 -0.017872 0.043511"/>
      <geometry>
        <mesh filename="package://snake_robot_cit_description/meshes/onemodule8_1.stl" scale="0.001 0.001 0.001"/>
      </geometry>
      <material name="default"/>
    </visual>
    <collision>
      <origin rpy="0 0 0" xyz="-0.494292 -0.017872 0.043511"/>
      <geometry>
        <mesh filename="package://snake_robot_cit_description/meshes/onemodule8_1.stl" scale="0.001 0.001 0.001"/>
      </geometry>
    </collision>
  </link>
  <link name="onemodule9_1">
    <inertial>
      <origin rpy="0 0 0" xyz="-6.739119111642822e-06 -0.06684337470880765 0.04508231470839009"/>
      <mass value="0.718982525570161"/>
      <inertia ixx="0.001158" ixy="3e-06" ixz="0.0" iyy="0.001136" iyz="2.8e-05" izz="0.001592"/>
    </inertial>
    <visual>
      <origin rpy="0 0 0" xyz="-0.494411 0.124128 0.043511"/>
      <geometry>
        <mesh filename="package://snake_robot_cit_description/meshes/onemodule9_1.stl" scale="0.001 0.001 0.001"/>
      </geometry>
      <material name="default"/>
    </visual>
    <collision>
      <origin rpy="0 0 0" xyz="-0.494411 0.124128 0.043511"/>
      <geometry>
        <mesh filename="package://snake_robot_cit_description/meshes/onemodule9_1.stl" scale="0.001 0.001 0.001"/>
      </geometry>
    </collision>
  </link>
  <link name="tailmodule_1">
    <inertial>
      <origin rpy="0 0 0" xyz="0.0001023758869976854 -0.14845328640353694 0.06592679604033103"/>
      <mass value="2.1589988659404105"/>
      <inertia ixx="0.009443" ixy="1.1e-05" ixz="-1e-06" iyy="0.004196" iyz="0.000381" izz="0.009702"/>
    </inertial>
    <visual>
      <origin rpy="0 0 0" xyz="-0.49453 0.266128 0.043511"/>
      <geometry>
        <mesh filename="package://snake_robot_cit_description/meshes/tailmodule_1.stl" scale="0.001 0.001 0.001"/>
      </geometry>
      <material name="default"/>
    </visual>
    <collision>
      <origin rpy="0 0 0" xyz="-0.49453 0.266128 0.043511"/>
      <geometry>
        <mesh filename="package://snake_robot_cit_description/meshes/tailmodule_1.stl" scale="0.001 0.001 0.001"/>
      </geometry>
    </collision>
  </link>
  <joint name="revjoint1" type="revolute">
    <origin rpy="0 0 0" xyz="0.493459 1.011872 -0.043511"/>
    <parent link="base_link"/>
    <child link="onemodule1_1"/>
    <axis xyz="-0.0 0.0 1.0"/>
    <limit effort="100" lower="-1.047198" upper="1.047198" velocity="100"/>
  </joint>
  <joint name="revjoint2" type="revolute">
    <origin rpy="0 0 0" xyz="0.000119 -0.142 0.0"/>
    <parent link="onemodule1_1"/>
    <child link="onemodule2_1"/>
    <axis xyz="-0.0 0.0 1.0"/>
    <limit effort="100" lower="-1.047198" upper="1.047198" velocity="100"/>
  </joint>
  <joint name="revjoint3" type="revolute">
    <origin rpy="0 0 0" xyz="0.000119 -0.142 0.0"/>
    <parent link="onemodule2_1"/>
    <child link="onemodule3_1"/>
    <axis xyz="-0.0 0.0 1.0"/>
    <limit effort="100" lower="-1.047198" upper="1.047198" velocity="100"/>
  </joint>
  <joint name="revjoint4" type="revolute">
    <origin rpy="0 0 0" xyz="0.000119 -0.142 0.0"/>
    <parent link="onemodule3_1"/>
    <child link="onemodule4_1"/>
    <axis xyz="-0.0 0.0 1.0"/>
    <limit effort="100" lower="-1.047198" upper="1.047198" velocity="100"/>
  </joint>
  <joint name="revjoint5" type="revolute">
    <origin rpy="0 0 0" xyz="0.000119 -0.142 0.0"/>
    <parent link="onemodule4_1"/>
    <child link="onemodule5_1"/>
    <axis xyz="-0.0 0.0 1.0"/>
    <limit effort="100" lower="-1.047198" upper="1.047198" velocity="100"/>
  </joint>
  <joint name="revjoint6" type="revolute">
    <origin rpy="0 0 0" xyz="0.000119 -0.142 0.0"/>
    <parent link="onemodule5_1"/>
    <child link="onemodule6_1"/>
    <axis xyz="-0.0 0.0 1.0"/>
    <limit effort="100" lower="-1.047198" upper="1.047198" velocity="100"/>
  </joint>
  <joint name="revjoint7" type="revolute">
    <origin rpy="0 0 0" xyz="0.000119 -0.142 0.0"/>
    <parent link="onemodule6_1"/>
    <child link="onemodule7_1"/>
    <axis xyz="-0.0 0.0 1.0"/>
    <limit effort="100" lower="-1.047198" upper="1.047198" velocity="100"/>
  </joint>
  <joint name="revjoint8" type="revolute">
    <origin rpy="0 0 0" xyz="0.000119 -0.142 0.0"/>
    <parent link="onemodule7_1"/>
    <child link="onemodule8_1"/>
    <axis xyz="-0.0 0.0 1.0"/>
    <limit effort="100" lower="-1.047198" upper="1.047198" velocity="100"/>
  </joint>
  <joint name="revjoint9" type="revolute">
    <origin rpy="0 0 0" xyz="0.000119 -0.142 0.0"/>
    <parent link="onemodule8_1"/>
    <child link="onemodule9_1"/>
    <axis xyz="-0.0 0.0 1.0"/>
    <limit effort="100" lower="-1.047198" upper="1.047198" velocity="100"/>
  </joint>
  <joint name="revjoint10" type="revolute">
    <origin rpy="0 0 0" xyz="0.000119 -0.142 0.0"/>
    <parent link="onemodule9_1"/>
    <child link="tailmodule_1"/>
    <axis xyz="-0.0 0.0 1.0"/>
    <limit effort="100" lower="-1.047198" upper="1.047198" velocity="100"/>
  </joint>
</robot>
