<?xml version="1.0" ?>
<!-- =================================================================================== -->
<!-- |    This document was autogenerated by xacro from ./snake_robot_cit_description/urdf/snake_robot_cit.xacro | -->
<!-- |    EDITING THIS FILE BY HAND IS NOT RECOMMENDED                                 | -->
<!-- =================================================================================== -->
<robot name="snake_robot_cit">
  <material name="silver_default">
    <color rgba="0.700 0.700 0.700 1.000"/>
  </material>
  <material name="default">
    <color rgba="0.3137254901960784 0.3137254901960784 0.3137254901960784 1.0"/>
  </material>
  <transmission name="revjoint1_tran">
    <type>transmission_interface/SimpleTransmission</type>
    <joint name="revjoint1">
      <hardwareInterface>hardware_interface/EffortJointInterface</hardwareInterface>
    </joint>
    <actuator name="revjoint1_actr">
      <hardwareInterface>hardware_interface/EffortJointInterface</hardwareInterface>
      <mechanicalReduction>1</mechanicalReduction>
    </actuator>
  </transmission>
  <transmission name="revjoint2_tran">
    <type>transmission_interface/SimpleTransmission</type>
    <joint name="revjoint2">
      <hardwareInterface>hardware_interface/EffortJointInterface</hardwareInterface>
    </joint>
    <actuator name="revjoint2_actr">
      <hardwareInterface>hardware_interface/EffortJointInterface</hardwareInterface>
      <mechanicalReduction>1</mechanicalReduction>
    </actuator>
  </transmission>
  <transmission name="revjoint3_tran">
    <type>transmission_interface/SimpleTransmission</type>
    <joint name="revjoint3">
      <hardwareInterface>hardware_interface/EffortJointInterface</hardwareInterface>
    </joint>
    <actuator name="revjoint3_actr">
      <hardwareInterface>hardware_interface/EffortJointInterface</hardwareInterface>
      <mechanicalReduction>1</mechanicalReduction>
    </actuator>
  </transmission>
  <transmission name="revjoint4_tran">
    <type>transmission_interface/SimpleTransmission</type>
    <joint name="revjoint4">
      <hardwareInterface>hardware_interface/EffortJointInterface</hardwareInterface>
    </joint>
    <actuator name="revjoint4_actr">
      <hardwareInterface>hardware_interface/EffortJointInterface</hardwareInterface>
      <mechanicalReduction>1</mechanicalReduction>
    </actuator>
  </transmission>
  <transmission name="revjoint5_tran">
    <type>transmission_interface/SimpleTransmission</type>
    <joint name="revjoint5">
      <hardwareInterface>hardware_interface/EffortJointInterface</hardwareInterface>
    </joint>
    <actuator name="revjoint5_actr">
      <hardwareInterface>hardware_interface/EffortJointInterface</hardwareInterface>
      <mechanicalReduction>1</mechanicalReduction>
    </actuator>
  </transmission>
  <transmission name="revjoint6_tran">
    <type>transmission_interface/SimpleTransmission</type>
    <joint name="revjoint6">
      <hardwareInterface>hardware_interface/EffortJointInterface</hardwareInterface>
    </joint>
    <actuator name="revjoint6_actr">
      <hardwareInterface>hardware_interface/EffortJointInterface</hardwareInterface>
      <mechanicalReduction>1</mechanicalReduction>
    </actuator>
  </transmission>
  <transmission name="revjoint7_tran">
    <type>transmission_interface/SimpleTransmission</type>
    <joint name="revjoint7">
      <hardwareInterface>hardware_interface/EffortJointInterface</hardwareInterface>
    </joint>
    <actuator name="revjoint7_actr">
      <hardwareInterface>hardware_interface/EffortJointInterface</hardwareInterface>
      <mechanicalReduction>1</mechanicalReduction>
    </actuator>
  </transmission>
  <transmission name="revjoint8_tran">
    <type>transmission_interface/SimpleTransmission</type>
    <joint name="revjoint8">
      <hardwareInterface>hardware_interface/EffortJointInterface</hardwareInterface>
    </joint>
    <actuator name="revjoint8_actr">
      <hardwareInterface>hardware_interface/EffortJointInterface</hardwareInterface>
      <mechanicalReduction>1</mechanicalReduction>
    </actuator>
  </transmission>
  <transmission name="revjoint9_tran">
    <type>transmission_interface/SimpleTransmission</type>
    <joint name="revjoint9">
      <hardwareInterface>hardware_interface/EffortJointInterface</hardwareInterface>
    </joint>
    <actuator name="revjoint9_actr">
      <hardwareInterface>hardware_interface/EffortJointInterface</hardwareInterface>
      <mechanicalReduction>1</mechanicalReduction>
    </actuator>
  </transmission>
  <transmission name="revjoint10_tran">
    <type>transmission_interface/SimpleTransmission</type>
    <joint name="revjoint10">
      <hardwareInterface>hardware_interface/EffortJointInterface</hardwareInterface>
    </joint>
    <actuator name="revjoint10_actr">
      <hardwareInterface>hardware_interface/EffortJointInterface</hardwareInterface>
      <mechanicalReduction>1</mechanicalReduction>
    </actuator>
  </transmission>
  <link name="base_link">
    <inertial>
      <origin rpy="0 0 0" xyz="0.49333731311283335 1.158454640943659 0.019785748921786316"/>
      <mass value="2.4672394368378052"/>
      <inertia ixx="0.013192" ixy="7e-06" ixz="-0.0" iyy="0.00469" iyz="0.000587" izz="0.013535"/>
    </inertial>
    <visual>
      <origin rpy="0 0 0" xyz="0 0 0"/>
      <geometry>
        <mesh filename="package://snake_robot_cit_description/meshes/base_link.stl" scale="0.001 0.001 0.001"/>
      </geometry>
      <material name="default"/>
    </visual>
    <collision>
      <origin rpy="0 0 0" xyz="0 0 0"/>
      <geometry>
        <mesh filename="package://snake_robot_cit_description/meshes/base_link.stl" scale="0.001 0.001 0.001"/>
      </geometry>
    </collision>
  </link>
  <link name="onemodule1_1">
    <inertial>
      <origin rpy="0 0 0" xyz="9.454935828268063e-06 -0.06824295183345996 0.0390798362460684"/>
      <mass value="0.5901583787089195"/>
      <inertia ixx="0.000908" ixy="2e-06" ixz="-0.0" iyy="0.000902" iyz="5.1e-05" izz="0.001362"/>
    </inertial>
    <visual>
      <origin rpy="0 0 0" xyz="-0.493459 -1.011872 0.043511"/>
      <geometry>
        <mesh filename="package://snake_robot_cit_description/meshes/onemodule1_1.stl" scale="0.001 0.001 0.001"/>
      </geometry>
      <material name="default"/>
    </visual>
    <collision>
      <origin rpy="0 0 0" xyz="-0.493459 -1.011872 0.043511"/>
      <geometry>
        <mesh filename="package://snake_robot_cit_description/meshes/onemodule1_1.stl" scale="0.001 0.001 0.001"/>
      </geometry>
    </collision>
  </link>
  <link name="onemodule2_1">
    <inertial>
      <origin rpy="0 0 0" xyz="9.416544180018693e-06 -0.06824287867547296 0.03907983624606862"/>
      <mass value="0.5901583787089195"/>
      <inertia ixx="0.000908" ixy="2e-06" ixz="-0.0" iyy="0.000902" iyz="5.1e-05" izz="0.001362"/>
    </inertial>
    <visual>
      <origin rpy="0 0 0" xyz="-0.493578 -0.869872 0.043511"/>
      <geometry>
        <mesh filename="package://snake_robot_cit_description/meshes/onemodule2_1.stl" scale="0.001 0.001 0.001"/>
      </geometry>
      <material name="default"/>
    </visual>
    <collision>
      <origin rpy="0 0 0" xyz="-0.493578 -0.869872 0.043511"/>
      <geometry>
        <mesh filename="package://snake_robot_cit_description/meshes/onemodule2_1.stl" scale="0.001 0.001 0.001"/>
      </geometry>
    </collision>
  </link>
  <link name="onemodule3_1">
    <inertial>
      <origin rpy="0 0 0" xyz="9.378152531991368e-06 -0.06824280551748596 0.039079836246068825"/>
      <mass value="0.5901583787089195"/>
      <inertia ixx="0.000908" ixy="2e-06" ixz="-0.0" iyy="0.000902" iyz="5.1e-05" izz="0.001362"/>
    </inertial>
    <visual>
      <origin rpy="0 0 0" xyz="-0.493697 -0.727872 0.043511"/>
      <geometry>
        <mesh filename="package://snake_robot_cit_description/meshes/onemodule3_1.stl" scale="0.001 0.001 0.001"/>
      </geometry>
      <material name="default"/>
    </visual>
    <collision>
      <origin rpy="0 0 0" xyz="-0.493697 -0.727872 0.043511"/>
      <geometry>
        <mesh filename="package://snake_robot_cit_description/meshes/onemodule3_1.stl" scale="0.001 0.001 0.001"/>
      </geometry>
    </collision>
  </link>
  <link name="onemodule4_1">
    <inertial>
      <origin rpy="0 0 0" xyz="9.33976088379751e-06 -0.0682427323594984 0.03907983624606904"/>
      <mass value="0.5901583787089195"/>
      <inertia ixx="0.000908" ixy="2e-06" ixz="-0.0" iyy="0.000902" iyz="5.1e-05" izz="0.001362"/>
    </inertial>
    <visual>
      <origin rpy="0 0 0" xyz="-0.493816 -0.585872 0.043511"/>
      <geometry>
        <mesh filename="package://snake_robot_cit_description/meshes/onemodule4_1.stl" scale="0.001 0.001 0.001"/>
      </geometry>
      <material name="default"/>
    </visual>
    <collision>
      <origin rpy="0 0 0" xyz="-0.493816 -0.585872 0.043511"/>
      <geometry>
        <mesh filename="package://snake_robot_cit_description/meshes/onemodule4_1.stl" scale="0.001 0.001 0.001"/>
      </geometry>
    </collision>
  </link>
  <link name="onemodule5_1">
    <inertial>
      <origin rpy="0 0 0" xyz="9.301369235659163e-06 -0.0682426592015109 0.039079836246069255"/>
      <mass value="0.5901583787089195"/>
      <inertia ixx="0.000908" ixy="2e-06" ixz="-0.0" iyy="0.000902" iyz="5.1e-05" izz="0.001362"/>
    </inertial>
    <visual>
      <origin rpy="0 0 0" xyz="-0.493935 -0.443872 0.043511"/>
      <geometry>
        <mesh filename="package://snake_robot_cit_description/meshes/onemodule5_1.stl" scale="0.001 0.001 0.001"/>
      </geometry>
      <material name="default"/>
    </visual>
    <collision>
      <origin rpy="0 0 0" xyz="-0.493935 -0.443872 0.043511"/>
      <geometry>
        <mesh filename="package://snake_robot_cit_description/meshes/onemodule5_1.stl" scale="0.001 0.001 0.001"/>
      </geometry>
    </collision>
  </link>
  <link name="onemodule6_1">
    <inertial>
      <origin rpy="0 0 0" xyz="9.262977587465304e-06 -0.06824258604352332 0.03907983624606947"/>
      <mass value="0.5901583787089195"/>
      <inertia ixx="0.000908" ixy="2e-06" ixz="-0.0" iyy="0.000902" iyz="5.1e-05" izz="0.001362"/>
    </inertial>
    <visual>
      <origin rpy="0 0 0" xyz="-0.494054 -0.301872 0.043511"/>
      <geometry>
        <mesh filename="package://snake_robot_cit_description/meshes/onemodule6_1.stl" scale="0.001 0.001 0.001"/>
      </geometry>
      <material name="default"/>
    </visual>
    <collision>
      <origin rpy="0 0 0" xyz="-0.494054 -0.301872 0.043511"/>
      <geometry>
        <mesh filename="package://snake_robot_cit_description/meshes/onemodule6_1.stl" scale="0.001 0.001 0.001"/>
      </geometry>
    </collision>
  </link>
  <link name="onemodule7_1">
    <inertial>
      <origin rpy="0 0 0" xyz="9.224585939715535e-06 -0.0682425128855356 0.03907983624606968"/>
      <mass value="0.5901583787089195"/>
      <inertia ixx="0.000908" ixy="2e-06" ixz="-0.0" iyy="0.000902" iyz="5.1e-05" izz="0.001362"/>
    </inertial>
    <visual>
      <origin rpy="0 0 0" xyz="-0.494173 -0.159872 0.043511"/>
      <geometry>
        <mesh filename="package://snake_robot_cit_description/meshes/onemodule7_1.stl" scale="0.001 0.001 0.001"/>
      </geometry>
      <material name="default"/>
    </visual>
    <collision>
      <origin rpy="0 0 0" xyz="-0.494173 -0.159872 0.043511"/>
      <geometry>
        <mesh filename="package://snake_robot_cit_description/meshes/onemodule7_1.stl" scale="0.001 0.001 0.001"/>
      </geometry>
    </collision>
  </link>
  <link name="onemodule8_1">
    <inertial>
      <origin rpy="0 0 0" xyz="9.186194291410654e-06 -0.06824243972754791 0.03907983624606989"/>
      <mass value="0.5901583787089195"/>
      <inertia ixx="0.000908" ixy="2e-06" ixz="-0.0" iyy="0.000902" iyz="5.1e-05" izz="0.001362"/>
    </inertial>
    <visual>
      <origin rpy="0 0 0" xyz="-0.494292 -0.017872 0.043511"/>
      <geometry>
        <mesh filename="package://snake_robot_cit_description/meshes/onemodule8_1.stl" scale="0.001 0.001 0.001"/>
      </geometry>
      <material name="default"/>
    </visual>
    <collision>
      <origin rpy="0 0 0" xyz="-0.494292 -0.017872 0.043511"/>
      <geometry>
        <mesh filename="package://snake_robot_cit_description/meshes/onemodule8_1.stl" scale="0.001 0.001 0.001"/>
      </geometry>
    </collision>
  </link>
  <link name="onemodule9_1">
    <inertial>
      <origin rpy="0 0 0" xyz="9.14780264338333e-06 -0.06824236656956022 0.03907983624607011"/>
      <mass value="0.5901583787089195"/>
      <inertia ixx="0.000908" ixy="2e-06" ixz="-0.0" iyy="0.000902" iyz="5.1e-05" izz="0.001362"/>
    </inertial>
    <visual>
      <origin rpy="0 0 0" xyz="-0.494411 0.124128 0.043511"/>
      <geometry>
        <mesh filename="package://snake_robot_cit_description/meshes/onemodule9_1.stl" scale="0.001 0.001 0.001"/>
      </geometry>
      <material name="default"/>
    </visual>
    <collision>
      <origin rpy="0 0 0" xyz="-0.494411 0.124128 0.043511"/>
      <geometry>
        <mesh filename="package://snake_robot_cit_description/meshes/onemodule9_1.stl" scale="0.001 0.001 0.001"/>
      </geometry>
    </collision>
  </link>
  <link name="tailmodule_1">
    <inertial>
      <origin rpy="0 0 0" xyz="0.00010237588699751887 -0.14845328640353722 0.0659267960403302"/>
      <mass value="2.1589988659404105"/>
      <inertia ixx="0.009443" ixy="1.1e-05" ixz="-1e-06" iyy="0.004196" iyz="0.000381" izz="0.009702"/>
    </inertial>
    <visual>
      <origin rpy="0 0 0" xyz="-0.49453 0.266128 0.043511"/>
      <geometry>
        <mesh filename="package://snake_robot_cit_description/meshes/tailmodule_1.stl" scale="0.001 0.001 0.001"/>
      </geometry>
      <material name="default"/>
    </visual>
    <collision>
      <origin rpy="0 0 0" xyz="-0.49453 0.266128 0.043511"/>
      <geometry>
        <mesh filename="package://snake_robot_cit_description/meshes/tailmodule_1.stl" scale="0.001 0.001 0.001"/>
      </geometry>
    </collision>
  </link>
  <joint name="revjoint1" type="revolute">
    <origin rpy="0 0 0" xyz="0.493459 1.011872 -0.043511"/>
    <parent link="base_link"/>
    <child link="onemodule1_1"/>
    <axis xyz="-0.0 0.0 1.0"/>
    <limit effort="100" lower="-1.047198" upper="1.047198" velocity="100"/>
  </joint>
  <joint name="revjoint2" type="revolute">
    <origin rpy="0 0 0" xyz="0.000119 -0.142 0.0"/>
    <parent link="onemodule1_1"/>
    <child link="onemodule2_1"/>
    <axis xyz="-0.0 0.0 1.0"/>
    <limit effort="100" lower="-1.047198" upper="1.047198" velocity="100"/>
  </joint>
  <joint name="revjoint3" type="revolute">
    <origin rpy="0 0 0" xyz="0.000119 -0.142 0.0"/>
    <parent link="onemodule2_1"/>
    <child link="onemodule3_1"/>
    <axis xyz="-0.0 0.0 1.0"/>
    <limit effort="100" lower="-1.047198" upper="1.047198" velocity="100"/>
  </joint>
  <joint name="revjoint4" type="revolute">
    <origin rpy="0 0 0" xyz="0.000119 -0.142 0.0"/>
    <parent link="onemodule3_1"/>
    <child link="onemodule4_1"/>
    <axis xyz="0.0 0.0 1.0"/>
    <limit effort="100" lower="-1.047198" upper="1.047198" velocity="100"/>
  </joint>
  <joint name="revjoint5" type="revolute">
    <origin rpy="0 0 0" xyz="0.000119 -0.142 0.0"/>
    <parent link="onemodule4_1"/>
    <child link="onemodule5_1"/>
    <axis xyz="0.0 0.0 1.0"/>
    <limit effort="100" lower="-1.047198" upper="1.047198" velocity="100"/>
  </joint>
  <joint name="revjoint6" type="revolute">
    <origin rpy="0 0 0" xyz="0.000119 -0.142 0.0"/>
    <parent link="onemodule5_1"/>
    <child link="onemodule6_1"/>
    <axis xyz="0.0 0.0 1.0"/>
    <limit effort="100" lower="-1.047198" upper="1.047198" velocity="100"/>
  </joint>
  <joint name="revjoint7" type="revolute">
    <origin rpy="0 0 0" xyz="0.000119 -0.142 0.0"/>
    <parent link="onemodule6_1"/>
    <child link="onemodule7_1"/>
    <axis xyz="0.0 0.0 1.0"/>
    <limit effort="100" lower="-1.047198" upper="1.047198" velocity="100"/>
  </joint>
  <joint name="revjoint8" type="revolute">
    <origin rpy="0 0 0" xyz="0.000119 -0.142 0.0"/>
    <parent link="onemodule7_1"/>
    <child link="onemodule8_1"/>
    <axis xyz="0.0 0.0 1.0"/>
    <limit effort="100" lower="-1.047198" upper="1.047198" velocity="100"/>
  </joint>
  <joint name="revjoint9" type="revolute">
    <origin rpy="0 0 0" xyz="0.000119 -0.142 0.0"/>
    <parent link="onemodule8_1"/>
    <child link="onemodule9_1"/>
    <axis xyz="0.0 0.0 1.0"/>
    <limit effort="100" lower="-1.047198" upper="1.047198" velocity="100"/>
  </joint>
  <joint name="revjoint10" type="revolute">
    <origin rpy="0 0 0" xyz="0.000119 -0.142 0.0"/>
    <parent link="onemodule9_1"/>
    <child link="tailmodule_1"/>
    <axis xyz="0.0 0.0 1.0"/>
    <limit effort="100" lower="-1.047198" upper="1.047198" velocity="100"/>
  </joint>
</robot>
